Workbook

Sheet RESUMEN SET DE PRUEBAS
A1: NOMBRE TESTING | B1: Set De Pruebas BD
A2: FECHA DE APLICACIÓN
A3: HORA INICIO
A4: HORA TERMINO | C4: VERSION | D4: 1
A5: RESUMEN SET DE PRUEBAS: INTEGRACIÓN DE BD | C5: RESPONSABLES TESTING
A6: USUARIOS RELACIONADOS: Administrador, clientes y reclutadores | C6: Equipo de Testing
A7: ID Caso de Prueba | B7: INTEGRACIÓN DE BD | C7: Exitosa | D7: Fallida | E7: Observaciones o mejoras a aplicar | F7: % APROB.
A8: RQF-PRUEBA 01 | B8: ='1ER SET PRUEBAS-INTEGRACION BD'!B3 -> Conexión BD | C8: x | F8: 0.85
A9: RQF-PRUEBA 02 | B9: ='1ER SET PRUEBAS-INTEGRACION BD'!B4 -> consulta de datos | C9: x
A10: RQF-PRUEBA 03 | B10: ='1ER SET PRUEBAS-INTEGRACION BD'!B5 -> Actualizacion de datos | C10: x
A11: RQF-PRUEBA 04 | B11: ='1ER SET PRUEBAS-INTEGRACION BD'!B6 -> Eliminacion de candidato o reclutador
E12: Insertar link vídeo o respaldo evidencias
A13: NOMBRE TESTING | B13: Set De Pruebas Funcionalidades Gestion de Usuarios
A14: FECHA DE APLICACIÓN
A15: HORA INICIO
A16: HORA TERMINO
A17: RESUMEN SET DE PRUEBAS: GESTION DE USUARIOS | C17: RESPONSABLES TESTING
A18: USUARIOS RELACIONADOS: Administrador, clientes y reclutador | C18: Equipo de Testing
A19: ID Caso de Prueba | B19: ARRIENDO ESTACIONAMIENTO | C19: Exitosa | D19: Fallida | E19: Observaciones o mejoras a aplicar | F19: % APROB.
A20: ='2DO SET PRUEBAS-GESTION USUARIO'!A3 -> RQF-H1-E1-PRUEBA 01 | B20: ='2DO SET PRUEBAS-GESTION USUARIO'!B3 -> Registro candidato | C20: x | F20: 0.7
A21: ='2DO SET PRUEBAS-GESTION USUARIO'!A4 -> RQF-H2-E1-PRUEBA 02 | B21: ='2DO SET PRUEBAS-GESTION USUARIO'!B4 -> Registro de candidato invalido | C21: x
A22: ='2DO SET PRUEBAS-GESTION USUARIO'!A5 -> RQF-H3-E1-PRUEBA 03 | B22: ='2DO SET PRUEBAS-GESTION USUARIO'!B5 -> Login de candidato | C22: x
A23: ='2DO SET PRUEBAS-GESTION USUARIO'!A6 -> RQF-H4-E1-PRUEBA 04 | B23: ='2DO SET PRUEBAS-GESTION USUARIO'!B6 -> Login fallido | C23: x
A24: ='2DO SET PRUEBAS-GESTION USUARIO'!A7 -> RQF-H5-E1-PRUEBA 05 | B24: ='2DO SET PRUEBAS-GESTION USUARIO'!B7 -> Gestion de candidatos y reclutadores por parte del admin | C24: x
E25: Insertar link vídeo o respaldo evidencias
A26: NOMBRE TESTING | B26: Pruebas de Funcionalidad Gestion de ofertas laborales
A27: FECHA DE APLICACIÓN
A28: HORA INICIO
A29: HORA TERMINO
A30: RESUMEN SET DE PRUEBAS: GESTION DE OFERTAS LABORALES | C30: RESPONSABLES TESTING
A31: USUARIOS RELACIONADOS: Administrador, reclutador y clientes | C31: Equipo de Testing
A32: ID Caso de Prueba | B32: Nombre Prueba | C32: Exitosa | D32: Fallida | E32: Observaciones o mejoras a aplicar | F32: % APROB.
A33: ='3ER SET PRUEBAS-GESTION OFERTAS'!A3 -> RQF-H1-E2-PRUEBA 01 | B33: ='3ER SET PRUEBAS-GESTION OFERTAS'!B3 -> Crear oferta laboral | C33: x | F33: 0.7
A34: ='3ER SET PRUEBAS-GESTION OFERTAS'!A4 -> RQF-H2-E2-PRUEBA 02 | B34: ='3ER SET PRUEBAS-GESTION OFERTAS'!B4 -> Crear una oferta incompleta | C34: x
A35: ='3ER SET PRUEBAS-GESTION OFERTAS'!A5 -> RQF-H2-E2-PRUEBA 03 | B35: ='3ER SET PRUEBAS-GESTION OFERTAS'!B5 -> Editar oferta | C35: x
A36: ='3ER SET PRUEBAS-GESTION OFERTAS'!A6 -> RQF-H2-E2-PRUEBA 04 | B36: ='3ER SET PRUEBAS-GESTION OFERTAS'!B6 -> Cerrar oferta | C36: x
A37: ='3ER SET PRUEBAS-GESTION OFERTAS'!A7 -> RQF-H3-E2-PRUEBA 05 | B37: ='3ER SET PRUEBAS-GESTION OFERTAS'!B7 -> Buscar oferta | C37: x
E38: Insertar link vídeo o respaldo evidencias
A39: NOMBRE TESTING | B39: Pruebas de Funcionalidad Gestion de postulacion
A40: FECHA DE APLICACIÓN
...

Sheet 1ER SET PRUEBAS-INTEGRACION BD
A1: SET DE PRUEBAS 1 | C1: INTEGRACION DE BD
A2: ID | B2: Caso de Prueba | C2: Descripción | D2: Pasos | E2: Resultado Esperado. | F2: Resultado Real | G2: Estado | H2: Evidencias
A3: RQF-PRUEBA 01 | B3: Conexión BD | C3: Validar la conexión entre back-end y postgress | D3: Levantar el servidor y ejecutar las migraciones | E3: BD conectada y tablas conectadas | F3: Conexion Correcta | G3: Realizado | H3: Carpeta de evidencias - video 1.1
A4: RQF-PRUEBA 02 | B4: consulta de datos | C4: Validar que el sistema pueda leer registros de la BD | D4: Registrar usuario. Iniciar sesion y consultar el perfil. | E4: Datos recuperados correctamente desde la BD | F4: El sistema lee los registros hechos en la base de datos | G4: Realizado | H4: Carpeta de evidencias - video 1.2
A5: RQF-PRUEBA 03 | B5: Actualizacion de datos | C5: Modificar datos de candidatos o reclutadores en BD | D5: Iniciar sesion e ir a apartado de perfil y ingresar a modificar datos | E5: Datos actualizados correctamente | F5: Modifica correctamente los datos del perfil | G5: Realizado | H5: Carpeta de evidencias - video 1.3
A6: RQF-PRUEBA 04 | B6: Eliminacion de candidato o reclutador | C6: Eliminacion de reclutador o candidato por medio del administrador | D6: iniciar sesion como admin y observar los apartados de reclutador o candidatos registrados | E6: Eliminacion de candidato o reclutador exitosa. | F6: Eliminacion correctamente del perfil | G6: Realizado | H6: Carpeta de evidencias - video 1.4

Sheet 2DO SET PRUEBAS-GESTION USUARIO
A1: SET DE PRUEBAS 2 | C1: GESTION DE USUARIOS E1
A2: ID | B2: Caso de Prueba | C2: Descripción | D2: Pasos | E2: Resultado Esperado. | F2: Resultado Real | G2: Estado | H2: Evidencias
A3: RQF-H1-E1-PRUEBA 01 | B3: Registro candidato | C3: Registrar candidato | D3: Ingresar a apartado de registro, y registrarse con datos validos | E3: Registro concretado correctamente | F3: Registra correctamente al candidato | G3: Realizado | H3: Carpeta evidencias - video 2.1
A4: RQF-H2-E1-PRUEBA 02 | B4: Registro de candidato invalido | C4: Registrar un candidato pero con datos no validos | D4: Ingresar a apartado de registro, y registrarse con datos no validos | E4: Que el registro no e logre concretar | F4: No realiza el registro del perfil invalido | G4: Realizado | H4: Carpeta evidencias - video 2.2
A5: RQF-H3-E1-PRUEBA 03 | B5: Login de candidato | C5: Iniciar sesion con los datos correctos del candidato | D5: Ingresar al apartado de iniciar sesion y ingresar los datos validos | E5: Que se inicie sesion correctamente | F5: Se realiza el login correctamente | G5: Realizado | H5: Carpeta evidencias - video 2.3
A6: RQF-H4-E1-PRUEBA 04 | B6: Login fallido | C6: Iniciar sesion como candidato pero con datos no validos | D6: Ingresar al apartado de iniciar sesion y ingresar datos no validos | E6: Que no se realice el inicio de sesion | F6: No se realiza el inicio de sesion con datos invalidos | G6: Realizado | H6: Carpeta evidencias - video 2.4
A7: RQF-H5-E1-PRUEBA 05 | B7: Gestion de candidatos y reclutadores por parte del admin | C7: Que el admin pueda modificar, eliminar y crear a lo reclutadores y candidatos | D7: Iniciar sesion como admin y visualizar los campos correspondientes | E7: Que permita al admin modificar y eliminar candidatos y que pueda modificar, eliminar y crear reclutadores | F7: Se realiza las modificaciones, eliminaciones, y creacion de perfiles | G7: Realizado | H7: Carpeta evidencias - video 2.5

Sheet 3ER SET PRUEBAS-GESTION OFERTAS
A1: SET DE PRUEBAS 3 | C1: Gestion de ofertas laborales E2
A2: ID | B2: Caso de Prueba | C2: Descripción | D2: Pasos | E2: Resultado Esperado. | F2: Resultado Real | G2: Estado | H2: Evidencias
A3: RQF-H1-E2-PRUEBA 01 | B3: Crear oferta laboral | C3: Como reclutador, que pueda realizar la creacion de una oferta laboral correctamente | D3: iniciar sesion como reclutador y ingresar al apartado de crear oferta | E3: Que se realice la creacion de la oferta laboral correctamente | F3: Se crea una oferta laboral correctamente | G3: Realizado | H3: Carpeta evidencia - video 3.1
A4: RQF-H2-E2-PRUEBA 02 | B4: Crear una oferta incompleta | C4: Realizar la creacion de una oferta laboral con los campos obligatorios incompletos | D4: iniciar sesion como reclutador y ingresar al apartado de crear oferta | E4: Que no se concrete la creacion de la oferta laboral | F4: No se realiza la creacion de la oferta laboral incompleta | G4: Realizado | H4: Carpeta evidencia - video 3.2
A5: RQF-H2-E2-PRUEBA 03 | B5: Editar oferta | C5: Como reclutador quiero ser capaz de modificar la ofertas que creo | D5: iniciar sesion como reclutador y seleccionar la ofeta que quiere modificar | E5: Que se realice la modificacion correctamente | F5: Se modifica correctamente | G5: Realizado | H5: Carpeta evidencia - video 3.3
A6: RQF-H2-E2-PRUEBA 04 | B6: Cerrar oferta | C6: Como reclutador quiero ser capaz de poder poner una oferta en cerrada | D6: iniciar sesion como reclutador y seleccionar la oferta que quiera cambiar su estado | E6: Que el cambio de estado a cerrada se realice correctamente | F6: Se realiza el cierre de la oferta correctamente | G6: Realizado | H6: Carpeta evidencia - video 3.4
A7: RQF-H3-E2-PRUEBA 05 | B7: Buscar oferta | C7: Como candidato quiero ser capaz de poder buscar mediante un filtro una oferta en especifico | D7: Iniciar sesion como candidato e ingresar al buscador/filtro | E7: Que se realice correctamente el filtro/busqueda | F7: Se encuentra la oferta laboral correctamente | G7: Realizado | H7: Carpeta evidencia - video 3.5

Sheet 4TO SET PRUEBAS-GES POSTULACION
A1: Set de pruebas 4 | B1: Gestion de Postulacion E3
A2: ID | B2: CASO DE PRUEBA | C2: DESCRIPCION | D2: PASO A PASO | E2: RESULTADO ESPERADO | F2: RESULTADO REAL | G2: ESTADO | H2: Evidencias
A3: RQF-H1-E3-PRUEBA 01 | B3: Postular a oferta | C3: Como candidato quiero ser capaz de lograr postularme a una oferta laboral | D3: Iniciar sesion como candidato y identificar oferta a postular e ingresar para postular | E3: Postulacion realizada correctamente | F3: Se realiza la postulacion correctamente | G3: Realizado | H3: Carpeta evidencia - video 4.1
A4: RQF-H1-E3-PRUEBA 02 | B4: Postulacion duplicada | C4: Como candidato quiero saber si esque puedo postularme 2 veces a la misma oferta | D4: Iniciar sesion como candidato y entrar a la misma oferta laboral en la que se postulo antes | E4: El proceso de postulacion no se realiza correctamente | F4: No se realiza la postulacion duplicada | G4: Realizado | H4: Carpeta evidencia - video 4.2
A5: RQF-H2-E3-PRUEBA 03 | B5: Consultar estado de mis postulaciones | C5: Como candidato quiero ser capaz de ver las postulaciones a las que ya postule | D5: Iniciar sesion como candidato he ingresar al apartado de mi perfil | E5: Lograr visualizar las postulaciones ya realizadas | F5: Se observa correctamente las postulaciones realizadas por el candidato | G5: Realizado | H5: Carpeta evidencia - video 4.3
A6: RQF-H3-E3-PRUEBA 04 | B6: Ver postulaciones recibidas | C6: Como reclutador quiero ser capaz de visualizar las postulaciones realizadas por los candidatos | D6: Iniciar sesion como reclutador he ingresar en el apartado | E6: Visualizar correctamente todas las postulaciones realizadas a las ofertas creadas por dicho reclutador | F6: Se observan correctamente las postulaciones realizadas por los candidatos | G6: Realizado | H6: Carpeta evidencia - video 4.4
A7: RQF-H3-E3-PRUEBA 05 | B7: Filtrar postulaciones por estado | C7: Como reclutador quiero poder aplicar un filtro según el estado de las postualciones | D7: Iniciar sesion como reclutador | E7: Filtro por estado realizado correctamente | F7: Se realiza la busqueda de filtro correctamente | G7: Realizado | H7: Carpeta evidencia - video 4.5

Sheet 5TO SET PRUEBAS-GES CONDIDATOS
A1: Set de pruebas 5 | B1: Gestion de candidatos E4
A2: ID | B2: CASO DE USO | C2: DESCRIPCION | D2: PASO A PASO | E2: RESULTADO ESPERADO | F2: RESULTADO REAL | G2: ESTADO | H2: EVIDENCIA
A3: RQF-H1-E4-PRUEBA 01 | B3: Cosultar perfil | C3: Como candidato quiero ser capaz de poder consultar los datos de mi perfil | D3: Iniciar sesion con una cuenta de candidato valida he ingresar al apartado de mi perfil | E3: Observar la consulta de los datos según el perfil correctamente | F3: Se muestran correctamente los datos del perfil | G3: Realizado | H3: Carpeta evidencias - video 5.1
A4: RQF-H1-E4-PRUEBA 02 | B4: Observar postulaciones | C4: Como candidato quiero poder ser capaz de observar las postulaciones que realizó | D4: Iniciar sesion y dirijirse al apartado de mis postulaciones | E4: Que se muestren las postulaciones realizadas correctamente | F4: Se observan correctamente las postulaciones realizadas por el candidato | G4: Realizado | H4: Carpeta evidencias - video 5.2
A5: RQF-H2-E4-PRUEBA 03 | B5: Actualizar informacion de perfil de candidato | C5: Como candiadto quiero poder realizar modificacion en la informacion de mi perfil | D5: Candidato realiza combios en la info de su perfil, guarda y vuelve a consultar | E5: Modificacion de datos de perfil realizada correctamente | F5: Se actualiza correctamente los datos del candidato | G5: Realizado | H5: Carpeta evidencias - video 5.3
A6: RQF-H1-E4-PRUEBA 04 | B6: Creacion de candidato duplicado | C6: Creacion de perfil de candidato que ya se ha creado anteriormente | D6: Ingresar al apartado de crear perfil y ingresar datos que ya se ingresaron anteriormente | E6: Creacion de candidato no realizada | F6: No se realiza la creacion del candidato duplicado | G6: Realizado | H6: Carpeta evidencias - video 5.4
A7: RQF-H1-E4-PRUEBA 05 | B7: Cambiar contraseñas | C7: Como candidato quiero poder modificar mi contraseña | D7: Iniciar sesion como candidato he ingresar al apartado de mi perfil. Ahí ingresar a cambiar contraseña | E7: Cambio de contraseña realizado correctamente | F7: Se realiza correctamente la modificacion de la contraseña | G7: Realizado | H7: Carpeta evidencias - video 5.5

Sheet 6TO SET PRUEBAS-GES ENTREVISTAS
A1: Set de pruebas 6 | B1: Gestion de entrevistas E5
A2: ID | B2: CASO DE PRUEBA | C2: DESCRIPCION | D2: PASO A PASO | E2: RESULTADO ESPERADO | F2: RESULTADO REAL | G2: ESTADO | H2: EVIDENCIAS
A3: RQF-H1-E5-PRUEBA 01 | B3: Agendar entrevista | C3: Como reclutador quiero ser capaz de poder agendar entrevista con el candidato seleccionado | D3: Ingresar al apartado de ofertas laborales con perfil de reclutador y seleccionar la oferta laboral en la que se quiere realizar la entrevista | E3: Realizacion de agendacion de estrevista realizada correctamente | F3: Se realiza correctamente la agendacion de la entrevista | G3: Realizado | H3: Carpeta evidencia - video 6.1
A4: RQF-H1-E5-PRUEBA 02 | B4: Agendar entrevista inválida | C4: Como reclutador quiero validar que la agendacion no funcione con datos invalidos | D4: Ingresar al apartado de ofertas laborales con perfil de reclutador y seleccionar la oferta laboral en la que se quiere realizar la entrevista | E4: Realizacion de agendacion de entrevista fallida | F4: No realiza la agendaccion de la entrevista | G4: Realizado | H4: Carpeta evidencia - video 6.2
A5: RQF-H2-E5-PRUEBA 03 | B5: Observaccion de las entrevistas | C5: Como reclutador quiero ser capaz de observar las entrevistas realizadas | D5: Iniciar sesion como reclutador y y al panel de entrevistas | E5: observar todas las entrevistas realizadas | F5: Se observa correctamente todas las entrevistas | G5: Realizado | H5: Carpeta evidencia - video 6.3

Sheet 7MO SET PRUEBAS-FUN GENERALES
A1: Set 7 de pruebas | B1: Funciones Generales
A2: ID | B2: CASOS DE USO | C2: DESCRIPCION | D2: PASO A PASO | E2: RESULTADO ESPERADO | F2: RESULTADO REAL | G2: ESTADO | H2: EVIDENCIA
A3: RQF-PRUEBA 01 | B3: Cifrado de contraseña | C3: La BD debe poder guardar las contraseñas de manera cifrada | D3: Registrarse como candidato o reclutador y observar en la BD la columna de contraseña | E3: Que la contraseña se guarde de manera cifrada | F3: La contraseña se cifra correctamente en la BD | G3: Realizado | H3: Carpeta evidencia - video 7.1
A4: RQF-PRUEBA 02 | B4: Redireccion mediante url | C4: Comprovar si al ingresar ciertos nombres en la url los redirije a ellos | D4: ingresar a la pagina y modificar la url | E4: Las vistas deben estar protegidas, por ende, no deberia poder ingresarse mediante redireccionamientos en la url | F4: Las vistas se encuentran protegidas por lo que si se intenta ingresar mediante la url se redirige a el inicio de sesion o directamente sale un mensaje de acceso denegado | G4: Realizado | H4: Carpeta evidencia - video 7.2
